Workbook

Sheet README
A1: Fantasy Draft Auction Assistant - Google Sheets Engine
A3: What this workbook is | B3: A first working engine for the auction draft assistant. Import this .xlsx into the blank Google Sheet, then populate the highlighted input fields.
A4: Best workflow | B4: Use Settings, Managers and Players before draft day. Use Live Draft during the draft. Use Auction Log to record completed sales.
A5: Built from existing data | B5: The 2025/26 auction result and player points data from your uploaded Draft Results.xlsx has been included in Historical Drafts and Historical Points.
A6: Important | B6: I could not edit the linked Google Sheet directly from this environment, so this workbook is designed to be imported into it.
A9: Populate before draft | B9: Where
A10: Confirm manager names and your manager name | B10: Settings + Managers
A11: Add/refresh full player pool if Fantrax export changes | B11: Players
A12: Enter site projections | B12: Players column N
A13: Enter your personal projections | B13: Players column O
A14: Review/override tiers | B14: Players column F
A15: Set preference score 1-10 | B15: Players column G
A16: Set reliability score 1-10 | B16: Players column H
... A19: Paste 2023/24 and 2024/25 data when available | B19: Historical Drafts / Historical Points
A22: How to use during the live draft
A24: 1 | B24: Go to Live Draft.
A25: 2 | B25: Select the nominated player from the dropdown/search field.
A26: 3 | B26: Use the bid recommendation cards to guide your bidding.
A27: 4 | B27: When the auction ends, enter sold price and winning manager.
A28: 5 | B28: Copy the generated row into Auction Log. This updates budgets, squads, market sentiment and future max bids.

Sheet Settings
A1: Auction Draft Settings
A3: Setting | B3: Value | C3: Notes | I3: Input | J3: Weight | K3: Notes
A4: Season | B4: 2026/27 | C4: Editable label only | I4: Your Projection | J4: 0.55 | K4: Primary input
A5: Manager Count | B5: 9 | C5: Adjust between 6 and 12 | I5: Previous Points | J5: 0.35 | K5: Useful because starter point rule continues
A6: Starting Budget | B6: 200 | C6: Default auction budget | I6: Site Projection | J6: 0.1 | K6: Weak external signal
A7: Squad Size | B7: 15 | C7: Each manager drafts exactly 15 players | I7: Risk Mode Hard Max Mult | J7: {=XLOOKUP($B$10,$Q$15:$Q$17,$S$15:$S$17,1)} -> 1 | K7: Formula from risk mode table
A8: Active Players | B8: 11 | C8: Starting XI | I8: Preference Influence | J8: 0.15 | K8: How much 1-10 preference moves value
A9: Bench Players | B9: 4 | C9: Squad size minus active players | I9: Reliability Influence | J9: 0.15 | K9: How much 1-10 reliability moves value
A10: Risk Mode | B10: Balanced | C10: Safe / Balanced / Upside | I10: Avoid Multiplier | J10: 0.7 | K10: Applied when Avoid Unless Cheap = Yes
A11: Starter Point Active | B11: Yes | C11: 1 point per player starting a fixture
A12: Your Manager Name | B12: The Clarke Arts Project | C12: Must match Managers sheet exactly
A13: First 10% Target | B13: 0.1 | C13: Strongly recommend drafting one player in this window
A14: Current Draft Pick | B14: =COUNTIF('Auction Log'!$B$3:$B$300,"<>")+1 -> 1 | C14: Formula-driven from Auction Log | I14: Tier | J14: Value Mult | K14: Opening % | L14: Good % | M14: Fair % | N14: Stretch % | O14: Hard Max % | Q14: Risk Mode | R14: Description | S14: Hard Max Mult
A15: Total Draft Picks | B15: =B5*B7 -> 135 | C15: Manager count x squad size | I15: Tier 1 | J15: 1.15 | K15: 0.45 | L15: 0.8 | M15: 1 | N15: 1.1 | O15: 1.18 | Q15: Safe | R15: Protects budget and avoids marginal overpays | S15: 0.95
I16: Tier 2 | J16: 1.05 | K16: 0.4 | L16: 0.78 | M16: 1 | N16: 1.06 | O16: 1.12 | Q16: Balanced | R16: Maximises value while keeping flexibility | S16: 1
I17: Tier 3 | J17: 1 | K17: 0.3 | L17: 0.7 | M17: 0.95 | N17: 1 | O17: 1.05 | Q17: Upside | R17: Allows stronger stretch on players you like | S17: 1.05
A18: Position | B18: Code | C18: Min Active | D18: Max Active | E18: Draft Min | F18: Max Squad | G18: Replacement Level | I18: Tier 4 | J18: 0.9 | K18: 0.25 | L18: 0.6 | M18: 0.85 | N18: 0.95 | O18: 1
A19: GK | B19: G | C19: 1 | D19: 1 | E19: 1 | F19: 3 | G19: 249.25 | I19: Tier 5 | J19: 0.75 | K19: 0.2 | L19: 0.5 | M19: 0.75 | N19: 0.85 | O19: 0.95
A20: DEF | B20: D | C20: 3 | D20: 5 | E20: 3 | F20: 7 | G20: 196.25 | I20: Watchlist | J20: 0.6 | K20: 0.1 | L20: 0.35 | M20: 0.6 | N20: 0.75 | O20: 0.85
A21: MID | B21: M | C21: 3 | D21: 5 | E21: 3 | F21: 7 | G21: 206
A22: FWD | B22: F | C22: 1 | D22: 3 | E22: 1 | F22: 6 | G22: 203
A25: Market Status | B25: Threshold | C25: Meaning
A26: Very Overheated | B26: 0.2 | C26: Actual spend is 20%+ above expected
A27: Overheated | B27: 0.08 | C27: Actual spend is 8%+ above expected
A28: Fair | B28: 0 | C28: Actual spend is close to expected
A29: Soft | B29: -0.08 | C29: Actual spend is 8%+ below expected
A30: Very Soft | B30: -0.2 | C30: Actual spend is 20%+ below expected

Sheet Managers
A1: Managers - Live Budget and Squad Tracking
A3: Manager ID | B3: Manager Name | C3: Active? | D3: Starting Budget | E3: Remaining Budget | F3: Players Drafted | G3: Squad Spots Left | H3: Max Legal Bid | I3: GK Drafted | J3: DEF Drafted | K3: MID Drafted | L3: FWD Drafted | M3: GK Need | N3: DEF Need | O3: MID Need | P3: FWD Need | Q3: Need Score | R3: Danger Level
A5: 1 | B5: Jase the Ace FC | C5: =IF(A5<=Settings!$B$5,"Yes","No") -> Yes | D5: =IF(C5="Yes",Settings!$B$6,"") -> 200 | E5: =IF(C5="Yes",D5-SUMIFS('Auction Log'!$F$3:$F$300,'Auction Log'!$G$3:$G$300,B5),"") -> 200 | F5: =IF(C5="Yes",COUNTIFS('Auction Log'!$G$3:$G$300,B5),"") -> 0 | G5: =IF(C5="Yes",Settings!$B$7-F5,"") -> 15 | H5: =IF(C5="Yes",MAX(0,E5-MAX(0,G5-1)),"") -> 186 | I5: =IF(C5="Yes",COUNTIFS('Auction Log'!$G$3:$G$300,B5,'Auction Log'!$D$3:$D$300,"GK"),"") -> 0 | J5: =IF(C5="Yes",COUNTIFS('Auction Log'!$G$3:$G$300,B5,'Auction Log'!$D$3:$D$300,"DEF"),"") -> 0 | K5: =IF(C5="Yes",COUNTIFS('Auction Log'!$G$3:$G$300,B5,'Auction Log'!$D$3:$D$300,"MID"),"") -> 0 | L5: =IF(C5="Yes",COUNTIFS('Auction Log'!$G$3:$G$300,B5,'Auction Log'!$D$3:$D$300,"FWD"),"") -> 0 | M5: {=IF(C5="Yes",MAX(0,XLOOKUP("GK",Settings!$A$19:$A$22,Settings!$E$19:$E$22)-I5),"")} -> 1 | N5: {=IF(C5="Yes",MAX(0,XLOOKUP("DEF",Settings!$A$19:$A$22,Settings!$E$19:$E$22)-J5),"")} -> 3 | O5: {=IF(C5="Yes",MAX(0,XLOOKUP("MID",Settings!$A$19:$A$22,Settings!$E$19:$E$22)-K5),"")} -> 3 | P5: {=IF(C5="Yes",MAX(0,XLOOKUP("FWD",Settings!$A$19:$A$22,Settings!$E$19:$E$22)-L5),"")} -> 1 | Q5: =IF(C5="Yes",SUM(M5:P5),"") -> 8 | R5: =IF(C5<>"Yes","",IF(H5>=LARGE($H$4:$H$15,MIN(3,Settings!$B$5)),"High",IF(H5>=AVERAGEIF($C$4:$C$15,"Yes",$H$4:$H$15),"Medium","Low"))) -> High
A6: 2 | B6: Bennett Like Beckham | C6: =IF(A6<=Settings!$B$5,"Yes","No") -> Yes | D6: =IF(C6="Yes",Settings!$B$6,"") -> 200 | E6: =IF(C6="Yes",D6-SUMIFS('Auction Log'!$F$3:$F$300,'Auction Log'!$G$3:$G$300,B6),"") -> 200 | F6: =IF(C6="Yes",COUNTIFS('Auction Log'!$G$3:$G$300,B6),"") -> 0 | G6: =IF(C6="Yes",Settings!$B$7-F6,"") -> 15 | H6: =IF(C6="Yes",MAX(0,E6-MAX(0,G6-1)),"") -> 186 | I6: =IF(C6="Yes",COUNTIFS('Auction Log'!$G$3:$G$300,B6,'Auction Log'!$D$3:$D$300,"GK"),"") -> 0 | J6: =IF(C6="Yes",COUNTIFS('Auction Log'!$G$3:$G$300,B6,'Auction Log'!$D$3:$D$300,"DEF"),"") -> 0 | K6: =IF(C6="Yes",COUNTIFS('Auction Log'!$G$3:$G$300,B6,'Auction Log'!$D$3:$D$300,"MID"),"") -> 0 | L6: =IF(C6="Yes",COUNTIFS('Auction Log'!$G$3:$G$300,B6,'Auction Log'!$D$3:$D$300,"FWD"),"") -> 0 | M6: {=IF(C6="Yes",MAX(0,XLOOKUP("GK",Settings!$A$19:$A$22,Settings!$E$19:$E$22)-I6),"")} -> 1 | N6: {=IF(C6="Yes",MAX(0,XLOOKUP("DEF",Settings!$A$19:$A$22,Settings!$E$19:$E$22)-J6),"")} -> 3 | O6: {=IF(C6="Yes",MAX(0,XLOOKUP("MID",Settings!$A$19:$A$22,Settings!$E$19:$E$22)-K6),"")} -> 3 | P6: {=IF(C6="Yes",MAX(0,XLOOKUP("FWD",Settings!$A$19:$A$22,Settings!$E$19:$E$22)-L6),"")} -> 1 | Q6: =IF(C6="Yes",SUM(M6:P6),"") -> 8 | R6: =IF(C6<>"Yes","",IF(H6>=LARGE($H$4:$H$15,MIN(3,Settings!$B$5)),"High",IF(H6>=AVERAGEIF($C$4:$C$15,"Yes",$H$4:$H$15),"Medium","Low"))) -> High
A7: 3 | B7: Wright on Time FC | C7: =IF(A7<=Settings!$B$5,"Yes","No") -> Yes | D7: =IF(C7="Yes",Settings!$B$6,"") -> 200 | E7: =IF(C7="Yes",D7-SUMIFS('Auction Log'!$F$3:$F$300,'Auction Log'!$G$3:$G$300,B7),"") -> 200 | F7: =IF(C7="Yes",COUNTIFS('Auction Log'!$G$3:$G$300,B7),"") -> 0 | G7: =IF(C7="Yes",Settings!$B$7-F7,"") -> 15 | H7: =IF(C7="Yes",MAX(0,E7-MAX(0,G7-1)),"") -> 186 | I7: =IF(C7="Yes",COUNTIFS('Auction Log'!$G$3:$G$300,B7,'Auction Log'!$D$3:$D$300,"GK"),"") -> 0 | J7: =IF(C7="Yes",COUNTIFS('Auction Log'!$G$3:$G$300,B7,'Auction Log'!$D$3:$D$300,"DEF"),"") -> 0 | K7: =IF(C7="Yes",COUNTIFS('Auction Log'!$G$3:$G$300,B7,'Auction Log'!$D$3:$D$300,"MID"),"") -> 0 | L7: =IF(C7="Yes",COUNTIFS('Auction Log'!$G$3:$G$300,B7,'Auction Log'!$D$3:$D$300,"FWD"),"") -> 0 | M7: {=IF(C7="Yes",MAX(0,XLOOKUP("GK",Settings!$A$19:$A$22,Settings!$E$19:$E$22)-I7),"")} -> 1 | N7: {=IF(C7="Yes",MAX(0,XLOOKUP("DEF",Settings!$A$19:$A$22,Settings!$E$19:$E$22)-J7),"")} -> 3 | O7: {=IF(C7="Yes",MAX(0,XLOOKUP("MID",Settings!$A$19:$A$22,Settings!$E$19:$E$22)-K7),"")} -> 3 | P7: {=IF(C7="Yes",MAX(0,XLOOKUP("FWD",Settings!$A$19:$A$22,Settings!$E$19:$E$22)-L7),"")} -> 1 | Q7: =IF(C7="Yes",SUM(M7:P7),"") -> 8 | R7: =IF(C7<>"Yes","",IF(H7>=LARGE($H$4:$H$15,MIN(3,Settings!$B$5)),"High",IF(H7>=AVERAGEIF($C$4:$C$15,"Yes",$H$4:$H$15),"Medium","Low"))) -> High
A8: 4 | B8: Calcio Birm FC | C8: =IF(A8<=Settings!$B$5,"Yes","No") -> Yes | D8: =IF(C8="Yes",Settings!$B$6,"") -> 200 | E8: =IF(C8="Yes",D8-SUMIFS('Auction Log'!$F$3:$F$300,'Auction Log'!$G$3:$G$300,B8),"") -> 200 | F8: =IF(C8="Yes",COUNTIFS('Auction Log'!$G$3:$G$300,B8),"") -> 0 | G8: =IF(C8="Yes",Settings!$B$7-F8,"") -> 15 | H8: =IF(C8="Yes",MAX(0,E8-MAX(0,G8-1)),"") -> 186 | I8: =IF(C8="Yes",COUNTIFS('Auction Log'!$G$3:$G$300,B8,'Auction Log'!$D$3:$D$300,"GK"),"") -> 0 | J8: =IF(C8="Yes",COUNTIFS('Auction Log'!$G$3:$G$300,B8,'Auction Log'!$D$3:$D$300,"DEF"),"") -> 0 | K8: =IF(C8="Yes",COUNTIFS('Auction Log'!$G$3:$G$300,B8,'Auction Log'!$D$3:$D$300,"MID"),"") -> 0 | L8: =IF(C8="Yes",COUNTIFS('Auction Log'!$G$3:$G$300,B8,'Auction Log'!$D$3:$D$300,"FWD"),"") -> 0 | M8: {=IF(C8="Yes",MAX(0,XLOOKUP("GK",Settings!$A$19:$A$22,Settings!$E$19:$E$22)-I8),"")} -> 1 | N8: {=IF(C8="Yes",MAX(0,XLOOKUP("DEF",Settings!$A$19:$A$22,Settings!$E$19:$E$22)-J8),"")} -> 3 | O8: {=IF(C8="Yes",MAX(0,XLOOKUP("MID",Settings!$A$19:$A$22,Settings!$E$19:$E$22)-K8),"")} -> 3 | P8: {=IF(C8="Yes",MAX(0,XLOOKUP("FWD",Settings!$A$19:$A$22,Settings!$E$19:$E$22)-L8),"")} -> 1 | Q8: =IF(C8="Yes",SUM(M8:P8),"") -> 8 | R8: =IF(C8<>"Yes","",IF(H8>=LARGE($H$4:$H$15,MIN(3,Settings!$B$5)),"High",IF(H8>=AVERAGEIF($C$4:$C$15,"Yes",$H$4:$H$15),"Medium","Low"))) -> High
A9: 5 | B9: Nisbet On Black | C9: =IF(A9<=Settings!$B$5,"Yes","No") -> Yes | D9: =IF(C9="Yes",Settings!$B$6,"") -> 200 | E9: =IF(C9="Yes",D9-SUMIFS('Auction Log'!$F$3:$F$300,'Auction Log'!$G$3:$G$300,B9),"") -> 200 | F9: =IF(C9="Yes",COUNTIFS('Auction Log'!$G$3:$G$300,B9),"") -> 0 | G9: =IF(C9="Yes",Settings!$B$7-F9,"") -> 15 | H9: =IF(C9="Yes",MAX(0,E9-MAX(0,G9-1)),"") -> 186 | I9: =IF(C9="Yes",COUNTIFS('Auction Log'!$G$3:$G$300,B9,'Auction Log'!$D$3:$D$300,"GK"),"") -> 0 | J9: =IF(C9="Yes",COUNTIFS('Auction Log'!$G$3:$G$300,B9,'Auction Log'!$D$3:$D$300,"DEF"),"") -> 0 | K9: =IF(C9="Yes",COUNTIFS('Auction Log'!$G$3:$G$300,B9,'Auction Log'!$D$3:$D$300,"MID"),"") -> 0 | L9: =IF(C9="Yes",COUNTIFS('Auction Log'!$G$3:$G$300,B9,'Auction Log'!$D$3:$D$300,"FWD"),"") -> 0 | M9: {=IF(C9="Yes",MAX(0,XLOOKUP("GK",Settings!$A$19:$A$22,Settings!$E$19:$E$22)-I9),"")} -> 1 | N9: {=IF(C9="Yes",MAX(0,XLOOKUP("DEF",Settings!$A$19:$A$22,Settings!$E$19:$E$22)-J9),"")} -> 3 | O9: {=IF(C9="Yes",MAX(0,XLOOKUP("MID",Settings!$A$19:$A$22,Settings!$E$19:$E$22)-K9),"")} -> 3 | P9: {=IF(C9="Yes",MAX(0,XLOOKUP("FWD",Settings!$A$19:$A$22,Settings!$E$19:$E$22)-L9),"")} -> 1 | Q9: =IF(C9="Yes",SUM(M9:P9),"") -> 8 | R9: =IF(C9<>"Yes","",IF(H9>=LARGE($H$4:$H$15,MIN(3,Settings!$B$5)),"High",IF(H9>=AVERAGEIF($C$4:$C$15,"Yes",$H$4:$H$15),"Medium","Low"))) -> High
A10: 6 | B10: Who Needs a Flan B? | C10: =IF(A10<=Settings!$B$5,"Yes","No") -> Yes | D10: =IF(C10="Yes",Settings!$B$6,"") -> 200 | E10: =IF(C10="Yes",D10-SUMIFS('Auction Log'!$F$3:$F$300,'Auction Log'!$G$3:$G$300,B10),"") -> 200 | F10: =IF(C10="Yes",COUNTIFS('Auction Log'!$G$3:$G$300,B10),"") -> 0 | G10: =IF(C10="Yes",Settings!$B$7-F10,"") -> 15 | H10: =IF(C10="Yes",MAX(0,E10-MAX(0,G10-1)),"") -> 186 | I10: =IF(C10="Yes",COUNTIFS('Auction Log'!$G$3:$G$300,B10,'Auction Log'!$D$3:$D$300,"GK"),"") -> 0 | J10: =IF(C10="Yes",COUNTIFS('Auction Log'!$G$3:$G$300,B10,'Auction Log'!$D$3:$D$300,"DEF"),"") -> 0 | K10: =IF(C10="Yes",COUNTIFS('Auction Log'!$G$3:$G$300,B10,'Auction Log'!$D$3:$D$300,"MID"),"") -> 0 | L10: =IF(C10="Yes",COUNTIFS('Auction Log'!$G$3:$G$300,B10,'Auction Log'!$D$3:$D$300,"FWD"),"") -> 0 | M10: {=IF(C10="Yes",MAX(0,XLOOKUP("GK",Settings!$A$19:$A$22,Settings!$E$19:$E$22)-I10),"")} -> 1 | N10: {=IF(C10="Yes",MAX(0,XLOOKUP("DEF",Settings!$A$19:$A$22,Settings!$E$19:$E$22)-J10),"")} -> 3 | O10: {=IF(C10="Yes",MAX(0,XLOOKUP("MID",Settings!$A$19:$A$22,Settings!$E$19:$E$22)-K10),"")} -> 3 | P10: {=IF(C10="Yes",MAX(0,XLOOKUP("FWD",Settings!$A$19:$A$22,Settings!$E$19:$E$22)-L10),"")} -> 1 | Q10: =IF(C10="Yes",SUM(M10:P10),"") -> 8 | R10: =IF(C10<>"Yes","",IF(H10>=LARGE($H$4:$H$15,MIN(3,Settings!$B$5)),"High",IF(H10>=AVERAGEIF($C$4:$C$15,"Yes",$H$4:$H$15),"Medium","Low"))) -> High
A11: 7 | B11: The Clarke Arts Project | C11: =IF(A11<=Settings!$B$5,"Yes","No") -> Yes | D11: =IF(C11="Yes",Settings!$B$6,"") -> 200 | E11: =IF(C11="Yes",D11-SUMIFS('Auction Log'!$F$3:$F$300,'Auction Log'!$G$3:$G$300,B11),"") -> 200 | F11: =IF(C11="Yes",COUNTIFS('Auction Log'!$G$3:$G$300,B11),"") -> 0 | G11: =IF(C11="Yes",Settings!$B$7-F11,"") -> 15 | H11: =IF(C11="Yes",MAX(0,E11-MAX(0,G11-1)),"") -> 186 | I11: =IF(C11="Yes",COUNTIFS('Auction Log'!$G$3:$G$300,B11,'Auction Log'!$D$3:$D$300,"GK"),"") -> 0 | J11: =IF(C11="Yes",COUNTIFS('Auction Log'!$G$3:$G$300,B11,'Auction Log'!$D$3:$D$300,"DEF"),"") -> 0 | K11: =IF(C11="Yes",COUNTIFS('Auction Log'!$G$3:$G$300,B11,'Auction Log'!$D$3:$D$300,"MID"),"") -> 0 | L11: =IF(C11="Yes",COUNTIFS('Auction Log'!$G$3:$G$300,B11,'Auction Log'!$D$3:$D$300,"FWD"),"") -> 0 | M11: {=IF(C11="Yes",MAX(0,XLOOKUP("GK",Settings!$A$19:$A$22,Settings!$E$19:$E$22)-I11),"")} -> 1 | N11: {=IF(C11="Yes",MAX(0,XLOOKUP("DEF",Settings!$A$19:$A$22,Settings!$E$19:$E$22)-J11),"")} -> 3 | O11: {=IF(C11="Yes",MAX(0,XLOOKUP("MID",Settings!$A$19:$A$22,Settings!$E$19:$E$22)-K11),"")} -> 3 | P11: {=IF(C11="Yes",MAX(0,XLOOKUP("FWD",Settings!$A$19:$A$22,Settings!$E$19:$E$22)-L11),"")} -> 1 | Q11: =IF(C11="Yes",SUM(M11:P11),"") -> 8 | R11: =IF(C11<>"Yes","",IF(H11>=LARGE($H$4:$H$15,MIN(3,Settings!$B$5)),"High",IF(H11>=AVERAGEIF($C$4:$C$15,"Yes",$H$4:$H$15),"Medium","Low"))) -> High
A12: 8 | B12: Flan the Man FC | C12: =IF(A12<=Settings!$B$5,"Yes","No") -> Yes | D12: =IF(C12="Yes",Settings!$B$6,"") -> 200 | E12: =IF(C12="Yes",D12-SUMIFS('Auction Log'!$F$3:$F$300,'Auction Log'!$G$3:$G$300,B12),"") -> 200 | F12: =IF(C12="Yes",COUNTIFS('Auction Log'!$G$3:$G$300,B12),"") -> 0 | G12: =IF(C12="Yes",Settings!$B$7-F12,"") -> 15 | H12: =IF(C12="Yes",MAX(0,E12-MAX(0,G12-1)),"") -> 186 | I12: =IF(C12="Yes",COUNTIFS('Auction Log'!$G$3:$G$300,B12,'Auction Log'!$D$3:$D$300,"GK"),"") -> 0 | J12: =IF(C12="Yes",COUNTIFS('Auction Log'!$G$3:$G$300,B12,'Auction Log'!$D$3:$D$300,"DEF"),"") -> 0 | K12: =IF(C12="Yes",COUNTIFS('Auction Log'!$G$3:$G$300,B12,'Auction Log'!$D$3:$D$300,"MID"),"") -> 0 | L12: =IF(C12="Yes",COUNTIFS('Auction Log'!$G$3:$G$300,B12,'Auction Log'!$D$3:$D$300,"FWD"),"") -> 0 | M12: {=IF(C12="Yes",MAX(0,XLOOKUP("GK",Settings!$A$19:$A$22,Settings!$E$19:$E$22)-I12),"")} -> 1 | N12: {=IF(C12="Yes",MAX(0,XLOOKUP("DEF",Settings!$A$19:$A$22,Settings!$E$19:$E$22)-J12),"")} -> 3 | O12: {=IF(C12="Yes",MAX(0,XLOOKUP("MID",Settings!$A$19:$A$22,Settings!$E$19:$E$22)-K12),"")} -> 3 | P12: {=IF(C12="Yes",MAX(0,XLOOKUP("FWD",Settings!$A$19:$A$22,Settings!$E$19:$E$22)-L12),"")} -> 1 | Q12: =IF(C12="Yes",SUM(M12:P12),"") -> 8 | R12: =IF(C12<>"Yes","",IF(H12>=LARGE($H$4:$H$15,MIN(3,Settings!$B$5)),"High",IF(H12>=AVERAGEIF($C$4:$C$15,"Yes",$H$4:$H$15),"Medium","Low"))) -> High
A13: 9 | B13: Over 2.5 Scholes | C13: =IF(A13<=Settings!$B$5,"Yes","No") -> Yes | D13: =IF(C13="Yes",Settings!$B$6,"") -> 200 | E13: =IF(C13="Yes",D13-SUMIFS('Auction Log'!$F$3:$F$300,'Auction Log'!$G$3:$G$300,B13),"") -> 200 | F13: =IF(C13="Yes",COUNTIFS('Auction Log'!$G$3:$G$300,B13),"") -> 0 | G13: =IF(C13="Yes",Settings!$B$7-F13,"") -> 15 | H13: =IF(C13="Yes",MAX(0,E13-MAX(0,G13-1)),"") -> 186 | I13: =IF(C13="Yes",COUNTIFS('Auction Log'!$G$3:$G$300,B13,'Auction Log'!$D$3:$D$300,"GK"),"") -> 0 | J13: =IF(C13="Yes",COUNTIFS('Auction Log'!$G$3:$G$300,B13,'Auction Log'!$D$3:$D$300,"DEF"),"") -> 0 | K13: =IF(C13="Yes",COUNTIFS('Auction Log'!$G$3:$G$300,B13,'Auction Log'!$D$3:$D$300,"MID"),"") -> 0 | L13: =IF(C13="Yes",COUNTIFS('Auction Log'!$G$3:$G$300,B13,'Auction Log'!$D$3:$D$300,"FWD"),"") -> 0 | M13: {=IF(C13="Yes",MAX(0,XLOOKUP("GK",Settings!$A$19:$A$22,Settings!$E$19:$E$22)-I13),"")} -> 1 | N13: {=IF(C13="Yes",MAX(0,XLOOKUP("DEF",Settings!$A$19:$A$22,Settings!$E$19:$E$22)-J13),"")} -> 3 | O13: {=IF(C13="Yes",MAX(0,XLOOKUP("MID",Settings!$A$19:$A$22,Settings!$E$19:$E$22)-K13),"")} -> 3 | P13: {=IF(C13="Yes",MAX(0,XLOOKUP("FWD",Settings!$A$19:$A$22,Settings!$E$19:$E$22)-L13),"")} -> 1 | Q13: =IF(C13="Yes",SUM(M13:P13),"") -> 8 | R13: =IF(C13<>"Yes","",IF(H13>=LARGE($H$4:$H$15,MIN(3,Settings!$B$5)),"High",IF(H13>=AVERAGEIF($C$4:$C$15,"Yes",$H$4:$H$15),"Medium","Low"))) -> High
A14: 10 | C14: =IF(A14<=Settings!$B$5,"Yes","No") -> No | D14: =IF(C14="Yes",Settings!$B$6,"") | E14: =IF(C14="Yes",D14-SUMIFS('Auction Log'!$F$3:$F$300,'Auction Log'!$G$3:$G$300,B14),"") | F14: =IF(C14="Yes",COUNTIFS('Auction Log'!$G$3:$G$300,B14),"") | G14: =IF(C14="Yes",Settings!$B$7-F14,"") | H14: =IF(C14="Yes",MAX(0,E14-MAX(0,G14-1)),"") | I14: =IF(C14="Yes",COUNTIFS('Auction Log'!$G$3:$G$300,B14,'Auction Log'!$D$3:$D$300,"GK"),"") | J14: =IF(C14="Yes",COUNTIFS('Auction Log'!$G$3:$G$300,B14,'Auction Log'!$D$3:$D$300,"DEF"),"") | K14: =IF(C14="Yes",COUNTIFS('Auction Log'!$G$3:$G$300,B14,'Auction Log'!$D$3:$D$300,"MID"),"") | L14: =IF(C14="Yes",COUNTIFS('Auction Log'!$G$3:$G$300,B14,'Auction Log'!$D$3:$D$300,"FWD"),"") | M14: {=IF(C14="Yes",MAX(0,XLOOKUP("GK",Settings!$A$19:$A$22,Settings!$E$19:$E$22)-I14),"")} | N14: {=IF(C14="Yes",MAX(0,XLOOKUP("DEF",Settings!$A$19:$A$22,Settings!$E$19:$E$22)-J14),"")} | O14: {=IF(C14="Yes",MAX(0,XLOOKUP("MID",Settings!$A$19:$A$22,Settings!$E$19:$E$22)-K14),"")} | P14: {=IF(C14="Yes",MAX(0,XLOOKUP("FWD",Settings!$A$19:$A$22,Settings!$E$19:$E$22)-L14),"")} | Q14: =IF(C14="Yes",SUM(M14:P14),"") | R14: =IF(C14<>"Yes","",IF(H14>=LARGE($H$4:$H$15,MIN(3,Settings!$B$5)),"High",IF(H14>=AVERAGEIF($C$4:$C$15,"Yes",$H$4:$H$15),"Medium","Low")))
A15: 11 | C15: =IF(A15<=Settings!$B$5,"Yes","No") -> No | D15: =IF(C15="Yes",Settings!$B$6,"") | E15: =IF(C15="Yes",D15-SUMIFS('Auction Log'!$F$3:$F$300,'Auction Log'!$G$3:$G$300,B15),"") | F15: =IF(C15="Yes",COUNTIFS('Auction Log'!$G$3:$G$300,B15),"") | G15: =IF(C15="Yes",Settings!$B$7-F15,"") | H15: =IF(C15="Yes",MAX(0,E15-MAX(0,G15-1)),"") | I15: =IF(C15="Yes",COUNTIFS('Auction Log'!$G$3:$G$300,B15,'Auction Log'!$D$3:$D$300,"GK"),"") | J15: =IF(C15="Yes",COUNTIFS('Auction Log'!$G$3:$G$300,B15,'Auction Log'!$D$3:$D$300,"DEF"),"") | K15: =IF(C15="Yes",COUNTIFS('Auction Log'!$G$3:$G$300,B15,'Auction Log'!$D$3:$D$300,"MID"),"") | L15: =IF(C15="Yes",COUNTIFS('Auction Log'!$G$3:$G$300,B15,'Auction Log'!$D$3:$D$300,"FWD"),"") | M15: {=IF(C15="Yes",MAX(0,XLOOKUP("GK",Settings!$A$19:$A$22,Settings!$E$19:$E$22)-I15),"")} | N15: {=IF(C15="Yes",MAX(0,XLOOKUP("DEF",Settings!$A$19:$A$22,Settings!$E$19:$E$22)-J15),"")} | O15: {=IF(C15="Yes",MAX(0,XLOOKUP("MID",Settings!$A$19:$A$22,Settings!$E$19:$E$22)-K15),"")} | P15: {=IF(C15="Yes",MAX(0,XLOOKUP("FWD",Settings!$A$19:$A$22,Settings!$E$19:$E$22)-L15),"")} | Q15: =IF(C15="Yes",SUM(M15:P15),"") | R15: =IF(C15<>"Yes","",IF(H15>=LARGE($H$4:$H$15,MIN(3,Settings!$B$5)),"High",IF(H15>=AVERAGEIF($C$4:$C$15,"Yes",$H$4:$H$15),"Medium","Low")))
A16: 12 | C16: =IF(A16<=Settings!$B$5,"Yes","No") -> No | D16: =IF(C16="Yes",Settings!$B$6,"") | E16: =IF(C16="Yes",D16-SUMIFS('Auction Log'!$F$3:$F$300,'Auction Log'!$G$3:$G$300,B16),"") | F16: =IF(C16="Yes",COUNTIFS('Auction Log'!$G$3:$G$300,B16),"") | G16: =IF(C16="Yes",Settings!$B$7-F16,"") | H16: =IF(C16="Yes",MAX(0,E16-MAX(0,G16-1)),"") | I16: =IF(C16="Yes",COUNTIFS('Auction Log'!$G$3:$G$300,B16,'Auction Log'!$D$3:$D$300,"GK"),"") | J16: =IF(C16="Yes",COUNTIFS('Auction Log'!$G$3:$G$300,B16,'Auction Log'!$D$3:$D$300,"DEF"),"") | K16: =IF(C16="Yes",COUNTIFS('Auction Log'!$G$3:$G$300,B16,'Auction Log'!$D$3:$D$300,"MID"),"") | L16: =IF(C16="Yes",COUNTIFS('Auction Log'!$G$3:$G$300,B16,'Auction Log'!$D$3:$D$300,"FWD"),"") | M16: {=IF(C16="Yes",MAX(0,XLOOKUP("GK",Settings!$A$19:$A$22,Settings!$E$19:$E$22)-I16),"")} | N16: {=IF(C16="Yes",MAX(0,XLOOKUP("DEF",Settings!$A$19:$A$22,Settings!$E$19:$E$22)-J16),"")} | O16: {=IF(C16="Yes",MAX(0,XLOOKUP("MID",Settings!$A$19:$A$22,Settings!$E$19:$E$22)-K16),"")} | P16: {=IF(C16="Yes",MAX(0,XLOOKUP("FWD",Settings!$A$19:$A$22,Settings!$E$19:$E$22)-L16),"")} | Q16: =IF(C16="Yes",SUM(M16:P16),"") | R16: =IF(C16<>"Yes","",IF(H16>=LARGE($H$4:$H$15,MIN(3,Settings!$B$5)),"High",IF(H16>=AVERAGEIF($C$4:$C$15,"Yes",$H$4:$H$15),"Medium","Low")))

Sheet Historical Drafts
A1: Historical Drafts - Auction Results
A3: Season | B3: Player ID | C3: Pick | D3: Position | E3: Player Name | F3: Team | G3: Bid | H3: Fantasy Team | I3: Time (BST) | J3: FPts | K3: FP/G | L3: Notes
A4: 2025/26 | B4: *03aqp* | C4: 1 | D4: FWD | E4: Mohamed Salah Ghaly | F4: LIV | G4: 69 | H4: Jase the Ace FC | I4: 45879.261 | J4: 285 | K4: 10.56
A5: 2025/26 | B5: *061vq* | C5: 2 | D5: FWD | E5: Erling Haaland | F5: MCI | G5: 67 | H5: Bennett Like Beckham | I5: 45879.262 | J5: 539 | K5: 15.4
A6: 2025/26 | B6: *06v21* | C6: 3 | D6: MID | E6: Florian Wirtz | F6: LIV | G6: 61 | H6: Jase the Ace FC | I6: 45879.264 | J6: 325.5 | K6: 9.86
A7: 2025/26 | B7: *05gcr* | C7: 4 | D7: MID | E7: Bruno Miguel Borges Fernandes | F7: MUN | G7: 62 | H7: Wright on Time FC | I7: 45879.265 | J7: 663 | K7: 18.94
A8: 2025/26 | B8: *05l8q* | C8: 5 | D8: MID | E8: Cole Palmer | F8: CHE | G8: 70 | H8: Calcio Birm FC | I8: 45879.267 | J8: 246 | K8: 9.46
A9: 2025/26 | B9: *04y92* | C9: 6 | D9: MID | E9: Bukayo Saka | F9: ARS | G9: 75 | H9: Wright on Time FC | I9: 45879.268 | J9: 437.5 | K9: 14.11
A10: 2025/26 | B10: *067yz* | C10: 7 | D10: FWD | E10: Matheus Santos Carneiro Da Cunha | F10: MUN | G10: 55 | H10: Nisbet On Black | I10: 45879.269 | J10: 352 | K10: 10.67
A11: 2025/26 | B11: *0646f* | C11: 8 | D11: FWD | E11: Alexander Isak | F11: NEW/LIV | G11: 66 | H11: Who Needs a Flan B? | I11: 45879.269 | J11: 64.5 | K11: 4.61
A12: 2025/26 | B12: *05ocl* | C12: 9 | D12: FWD | E12: Ollie Watkins | F12: AVL | G12: 41 | H12: The Clarke Arts Project | I12: 45879.272 | J12: 353.5 | K12: 9.55
A13: 2025/26 | B13: *05trb* | C13: 10 | D13: FWD | E13: Bryan Mbeumo | F13: MUN | G13: 42 | H13: Who Needs a Flan B? | I13: 45879.273 | J13: 336 | K13: 10.18
A14: 2025/26 | B14: *06rf9* | C14: 11 | D14: FWD | E14: Omar Khaled Mohamed Abd Elsala Marmoush | F14: MCI | G14: 42 | H14: Flan the Man FC | I14: 45879.274 | J14: 101.5 | K14: 4.83
A15: 2025/26 | B15: *05r9b* | C15: 12 | D15: MID | E15: Martin Odegaard | F15: ARS | G15: 38 | H15: Bennett Like Beckham | I15: 45879.275 | J15: 192 | K15: 8
... A153: 2025/26 | B153: *0520r* | C153: 150 | D153: MID | E153: Leandro Trossard | F153: ARS | G153: 1 | H153: Wright on Time FC | I153: 45879.388 | J153: 269 | K153: 8.68

Sheet Historical Points
A1: Historical Points - Player Points
A3: Season | B3: Player ID | C3: Player | D3: Team | E3: Position | F3: Overall Rank | G3: Status | H3: Opponent/Last Fixture | I3: FPts | J3: FP/G
A4: 2025/26 | B4: *05gcr* | C4: Bruno Fernandes | D4: MUN | E4: MID | F4: 1 | G4: LUC | H4: MUN 3 @BHA 0 F | I4: 663 | J4: 18.94
A5: 2025/26 | B5: *061vq* | C5: Erling Haaland | D5: MCI | E5: FWD | F5: 2 | G5: AFL | H5: AVL 2 @MCI 1 F | I5: 539 | J5: 15.4
A6: 2025/26 | B6: *068y0* | C6: Antoine Semenyo | D6: BOU/MCI | E6: FWD | F6: 3 | G6: RAM | H6: AVL 2 @MCI 1 F | I6: 462.5 | J6: 12.5
A7: 2025/26 | B7: *06mn0* | C7: Igor Thiago | D7: BRF | E7: FWD | F7: 4 | G7: RAM | H7: BRF 1 @LIV 1 F | I7: 452 | J7: 11.89
A8: 2025/26 | B8: *04y92* | C8: Bukayo Saka | D8: ARS | E8: MID | F8: 5 | G8: HAR | H8: ARS 2 @CRY 1 F | I8: 437.5 | J8: 14.11
A9: 2025/26 | B9: *04qr9* | C9: Morgan Gibbs-White | D9: NOT | E9: MID | F9: 6 | G9: BRD | H9: BOU 1 @NOT 1 F | I9: 435.5 | J9: 11.77
A10: 2025/26 | B10: *046c5* | C10: Jarrod Bowen | D10: WHU | E10: FWD | F10: 7 | G10: LUC | H10: LEE 0 @WHU 3 F | I10: 431 | J10: 11.34
A11: 2025/26 | B11: *04agz* | C11: Declan Rice | D11: ARS | E11: MID | F11: 8 | G11: SCH | H11: ARS 2 @CRY 1 F | I11: 420 | J11: 11.67
A12: 2025/26 | B12: *06cmm* | C12: Dominik Szoboszlai | D12: LIV | E12: MID | F12: 9 | G12: TBE | H12: BRF 1 @LIV 1 F | I12: 415.5 | J12: 11.54
A13: 2025/26 | B13: *05opj* | C13: Elliot Anderson | D13: NOT | E13: MID | F13: 10 | G13: RAM | H13: BOU 1 @NOT 1 F | I13: 405 | J13: 10.66
A14: 2025/26 | B14: *05g2o* | C14: Joao Pedro | D14: CHE | E14: FWD | F14: 11 | G14: JAS | H14: CHE 1 @SUN 2 F | I14: 393 | J14: 11.23
A15: 2025/26 | B15: *04spw* | C15: James Garner | D15: EVE | E15: MID | F15: 12 | G15: RAM | H15: EVE 0 @TOT 1 F | I15: 392.5 | J15: 10.33
... A923: 2025/26 | B923: *0620k* | C923: Nayef Aguerd | D923: WHU | E923: DEF | F923: 920 | G923: FA | H923: LEE 0 @WHU 3 F | I923: -5.25 | J923: -2.62

Sheet Lists
A1: Helper Lists and Multipliers
A2: Tiers | B2: Positions | C2: Transfer Risk | D2: Transfer Mult | E2: Yes/No | F2: Risk Modes | G2: Statuses | H2: Nomination Types
A3: Tier 1 | B3: GK | C3: Low | D3: 1 | E3: Yes | F3: Safe | G3: Available | H3: Target
A4: Tier 2 | B4: DEF | C4: Medium | D4: 0.9 | E4: No | F4: Balanced | G4: Sold | H4: Value Target
A5: Tier 3 | B5: MID | C5: High | D5: 0.75 | F5: Upside | H5: Budget Drainer
A6: Tier 4 | B6: FWD | C6: Expected Leave | D6: 0.4 | H6: Position Squeeze
A7: Tier 5 | C7: New Signing | D7: 0.95 | H7: Market Tester
A8: Watchlist | H8: Recommended

Sheet Players
A1: Players - Draft Board and Valuation Engine
A3: Player ID | B3: Player | C3: Team | D3: Eligible Pos | E3: Locked Pos | F3: Tier | G3: Preference 1-10 | H3: Reliability 1-10 | I3: Avoid Unless Cheap | J3: Transfer Risk | K3: Manual Review | L3: 2025/26 FPts | M3: 2025/26 FP/G | N3: Site Projection | O3: Your Projection | P3: Final Projection | Q3: Replacement Level | R3: Points Above Repl | S3: Base $ Value | T3: Tier Mult | U3: Preference Mult | V3: Reliability Mult | W3: Transfer Risk Mult | X3: Avoid Mult | Y3: Adjusted $ Value | Z3: Market $ Value | AA3: Status | AB3: Winning Manager | AC3: Sold Price | AD3: Opening Bid | AE3: Good Price | AF3: Fair Price | AG3: Stretch Price | AH3: Hard Max | AI3: Live Max Bid | AJ3: Nomination Type | AK3: Nomination Score | AL3: Notes
A4: *05gcr* | B4: Bruno Fernandes | C4: MUN | D4: MID | E4: MID | F4: Tier 1 | G4: 8 | H4: 7 | I4: No | J4: Low | L4: 663 | M4: 18.94 | P4: =IF($A4="","",IFERROR((IF($O4="",0,$O4)*Settings!$J$4+IF($L4="",0,$L4)*Settings!$J$5+IF($N4="",0,$N4)*Settings!$J$6)/(IF($O4="",0,Settings!$J$4)+IF($L4="",0,Settings!$J$5)+IF($N4="",0,Settings!$J$6)),0)) -> 663 | Q4: {=IF($A4="","",XLOOKUP($E4,Settings!$A$19:$A$22,Settings!$G$19:$G$22,0))} -> 206 | R4: =IF($A4="","",MAX(0,$P4-$Q4)) -> 457 | S4: =IF($A4="","",IF($R4<=0,1,1+$R4/SUMIF($R$4:$R$923,">0",$R$4:$R$923)*(Settings!$B$5*(Settings!$B$6-Settings!$B$7)))) -> 57.426029 | T4: {=IF($A4="","",XLOOKUP($F4,Settings!$I$15:$I$20,Settings!$J$15:$J$20,1))} -> 1.15 | U4: =IF($A4="","",1+(($G4-5)/5)*Settings!$J$8) -> 1.09 | V4: =IF($A4="","",1+(($H4-5)/5)*Settings!$J$9) -> 1.06 | W4: {=IF($A4="","",XLOOKUP($J4,Lists!$C$3:$C$7,Lists!$D$3:$D$7,1))} -> 1 | X4: =IF($A4="","",IF($I4="Yes",Settings!$J$10,1)) -> 1 | Y4: =IF($A4="","",MAX(1,ROUND($S4*$T4*$U4*$V4*$W4*$X4,0))) -> 76 | Z4: =IF($A4="","",IFERROR(ROUND(AVERAGEIFS('Historical Drafts'!$G$4:$G$300,'Historical Drafts'!$D$4:$D$300,$E4,'Historical Drafts'!$J$4:$J$300,">="&$L4*0.85,'Historical Drafts'!$J$4:$J$300,"<="&$L4*1.15),0),$Y4)) -> 62 | AA4: =IF($A4="","",IF(COUNTIF('Auction Log'!$B$3:$B$300,$A4)>0,"Sold","Available")) -> Available | AB4: {=IF($A4="","",IFERROR(XLOOKUP($A4,'Auction Log'!$B$3:$B$300,'Auction Log'!$G$3:$G$300,""),""))} | AC4: {=IF($A4="","",IFERROR(XLOOKUP($A4,'Auction Log'!$B$3:$B$300,'Auction Log'!$F$3:$F$300,""),""))} | AD4: {=IF($A4="","",ROUND($Y4*XLOOKUP($F4,Settings!$I$15:$I$20,Settings!$K$15:$K$20,0.4),0))} -> 34 | AE4: {=IF($A4="","",ROUND($Y4*XLOOKUP($F4,Settings!$I$15:$I$20,Settings!$L$15:$L$20,0.8),0))} -> 61 | AF4: {=IF($A4="","",ROUND($Y4*XLOOKUP($F4,Settings!$I$15:$I$20,Settings!$M$15:$M$20,1),0))} -> 76 | AG4: {=IF($A4="","",ROUND($Y4*XLOOKUP($F4,Settings!$I$15:$I$20,Settings!$N$15:$N$20,1.1),0))} -> 84 | AH4: {=IF($A4="","",ROUND($Y4*XLOOKUP($F4,Settings!$I$15:$I$20,Settings!$O$15:$O$20,1.1)*Settings!$J$7,0))} -> 90 | AI4: {=IF($A4="","",IF($AA4="Sold","",MIN($AH4,IFERROR(XLOOKUP(Settings!$B$12,Managers!$B$4:$B$15,Managers!$H$4:$H$15),$AH4))))} -> 90 | AJ4: =IF($A4="","",IF($AA4="Sold","Sold",IF($I4="Yes","Budget Drainer",IF($G4>=8,"Target",IF($Z4>$Y4*1.15,"Budget Drainer",IF($Y4>$Z4*1.15,"Value Target","Recommended")))))) -> Target | AK4: =IF($A4="","",IF($AA4="Sold",0,ROUND($Y4+$G4*5+IF($AJ4="Budget Drainer",MAX(0,$Z4-$Y4),0),0))) -> 116 | AL4: =IF($A4="","",IF($I4="Yes","Avoid unless cheap",IF($J4<>"Low","Check transfer risk","")))
A5: *061vq* | B5: Erling Haaland | C5: MCI | D5: FWD | E5: FWD | F5: Tier 1 | G5: 9 | H5: 7 | I5: No | J5: Low | L5: 539 | M5: 15.4 | P5: =IF($A5="","",IFERROR((IF($O5="",0,$O5)*Settings!$J$4+IF($L5="",0,$L5)*Settings!$J$5+IF($N5="",0,$N5)*Settings!$J$6)/(IF($O5="",0,Settings!$J$4)+IF($L5="",0,Settings!$J$5)+IF($N5="",0,Settings!$J$6)),0)) -> 539 | Q5: {=IF($A5="","",XLOOKUP($E5,Settings!$A$19:$A$22,Settings!$G$19:$G$22,0))} -> 203 | R5: =IF($A5="","",MAX(0,$P5-$Q5)) -> 336 | S5: =IF($A5="","",IF($R5<=0,1,1+$R5/SUMIF($R$4:$R$923,">0",$R$4:$R$923)*(Settings!$B$5*(Settings!$B$6-Settings!$B$7)))) -> 42.486096 | T5: {=IF($A5="","",XLOOKUP($F5,Settings!$I$15:$I$20,Settings!$J$15:$J$20,1))} -> 1.15 | U5: =IF($A5="","",1+(($G5-5)/5)*Settings!$J$8) -> 1.12 | V5: =IF($A5="","",1+(($H5-5)/5)*Settings!$J$9) -> 1.06 | W5: {=IF($A5="","",XLOOKUP($J5,Lists!$C$3:$C$7,Lists!$D$3:$D$7,1))} -> 1 | X5: =IF($A5="","",IF($I5="Yes",Settings!$J$10,1)) -> 1 | Y5: =IF($A5="","",MAX(1,ROUND($S5*$T5*$U5*$V5*$W5*$X5,0))) -> 58 | Z5: =IF($A5="","",IFERROR(ROUND(AVERAGEIFS('Historical Drafts'!$G$4:$G$300,'Historical Drafts'!$D$4:$D$300,$E5,'Historical Drafts'!$J$4:$J$300,">="&$L5*0.85,'Historical Drafts'!$J$4:$J$300,"<="&$L5*1.15),0),$Y5)) -> 50 | AA5: =IF($A5="","",IF(COUNTIF('Auction Log'!$B$3:$B$300,$A5)>0,"Sold","Available")) -> Available | AB5: {=IF($A5="","",IFERROR(XLOOKUP($A5,'Auction Log'!$B$3:$B$300,'Auction Log'!$G$3:$G$300,""),""))} | AC5: {=IF($A5="","",IFERROR(XLOOKUP($A5,'Auction Log'!$B$3:$B$300,'Auction Log'!$F$3:$F$300,""),""))} | AD5: {=IF($A5="","",ROUND($Y5*XLOOKUP($F5,Settings!$I$15:$I$20,Settings!$K$15:$K$20,0.4),0))} -> 26 | AE5: {=IF($A5="","",ROUND($Y5*XLOOKUP($F5,Settings!$I$15:$I$20,Settings!$L$15:$L$20,0.8),0))} -> 46 | AF5: {=IF($A5="","",ROUND($Y5*XLOOKUP($F5,Settings!$I$15:$I$20,Settings!$M$15:$M$20,1),0))} -> 58 | AG5: {=IF($A5="","",ROUND($Y5*XLOOKUP($F5,Settings!$I$15:$I$20,Settings!$N$15:$N$20,1.1),0))} -> 64 | AH5: {=IF($A5="","",ROUND($Y5*XLOOKUP($F5,Settings!$I$15:$I$20,Settings!$O$15:$O$20,1.1)*Settings!$J$7,0))} -> 68 | AI5: {=IF($A5="","",IF($AA5="Sold","",MIN($AH5,IFERROR(XLOOKUP(Settings!$B$12,Managers!$B$4:$B$15,Managers!$H$4:$H$15),$AH5))))} -> 68 | AJ5: =IF($A5="","",IF($AA5="Sold","Sold",IF($I5="Yes","Budget Drainer",IF($G5>=8,"Target",IF($Z5>$Y5*1.15,"Budget Drainer",IF($Y5>$Z5*1.15,"Value Target","Recommended")))))) -> Target | AK5: =IF($A5="","",IF($AA5="Sold",0,ROUND($Y5+$G5*5+IF($AJ5="Budget Drainer",MAX(0,$Z5-$Y5),0),0))) -> 103 | AL5: =IF($A5="","",IF($I5="Yes","Avoid unless cheap",IF($J5<>"Low","Check transfer risk","")))
A6: *068y0* | B6: Antoine Semenyo | C6: BOU/MCI | D6: FWD | E6: FWD | F6: Tier 1 | G6: 6 | H6: 7 | I6: No | J6: Low | L6: 462.5 | M6: 12.5 | P6: =IF($A6="","",IFERROR((IF($O6="",0,$O6)*Settings!$J$4+IF($L6="",0,$L6)*Settings!$J$5+IF($N6="",0,$N6)*Settings!$J$6)/(IF($O6="",0,Settings!$J$4)+IF($L6="",0,Settings!$J$5)+IF($N6="",0,Settings!$J$6)),0)) -> 462.5 | Q6: {=IF($A6="","",XLOOKUP($E6,Settings!$A$19:$A$22,Settings!$G$19:$G$22,0))} -> 203 | R6: =IF($A6="","",MAX(0,$P6-$Q6)) -> 259.5 | S6: =IF($A6="","",IF($R6<=0,1,1+$R6/SUMIF($R$4:$R$923,">0",$R$4:$R$923)*(Settings!$B$5*(Settings!$B$6-Settings!$B$7)))) -> 33.040601 | T6: {=IF($A6="","",XLOOKUP($F6,Settings!$I$15:$I$20,Settings!$J$15:$J$20,1))} -> 1.15 | U6: =IF($A6="","",1+(($G6-5)/5)*Settings!$J$8) -> 1.03 | V6: =IF($A6="","",1+(($H6-5)/5)*Settings!$J$9) -> 1.06 | W6: {=IF($A6="","",XLOOKUP($J6,Lists!$C$3:$C$7,Lists!$D$3:$D$7,1))} -> 1 | X6: =IF($A6="","",IF($I6="Yes",Settings!$J$10,1)) -> 1 | Y6: =IF($A6="","",MAX(1,ROUND($S6*$T6*$U6*$V6*$W6*$X6,0))) -> 41 | Z6: =IF($A6="","",IFERROR(ROUND(AVERAGEIFS('Historical Drafts'!$G$4:$G$300,'Historical Drafts'!$D$4:$D$300,$E6,'Historical Drafts'!$J$4:$J$300,">="&$L6*0.85,'Historical Drafts'!$J$4:$J$300,"<="&$L6*1.15),0),$Y6)) -> 41 | AA6: =IF($A6="","",IF(COUNTIF('Auction Log'!$B$3:$B$300,$A6)>0,"Sold","Available")) -> Available | AB6: {=IF($A6="","",IFERROR(XLOOKUP($A6,'Auction Log'!$B$3:$B$300,'Auction Log'!$G$3:$G$300,""),""))} | AC6: {=IF($A6="","",IFERROR(XLOOKUP($A6,'Auction Log'!$B$3:$B$300,'Auction Log'!$F$3:$F$300,""),""))} | AD6: {=IF($A6="","",ROUND($Y6*XLOOKUP($F6,Settings!$I$15:$I$20,Settings!$K$15:$K$20,0.4),0))} -> 18 | AE6: {=IF($A6="","",ROUND($Y6*XLOOKUP($F6,Settings!$I$15:$I$20,Settings!$L$15:$L$20,0.8),0))} -> 33 | AF6: {=IF($A6="","",ROUND($Y6*XLOOKUP($F6,Settings!$I$15:$I$20,Settings!$M$15:$M$20,1),0))} -> 41 | AG6: {=IF($A6="","",ROUND($Y6*XLOOKUP($F6,Settings!$I$15:$I$20,Settings!$N$15:$N$20,1.1),0))} -> 45 | AH6: {=IF($A6="","",ROUND($Y6*XLOOKUP($F6,Settings!$I$15:$I$20,Settings!$O$15:$O$20,1.1)*Settings!$J$7,0))} -> 48 | AI6: {=IF($A6="","",IF($AA6="Sold","",MIN($AH6,IFERROR(XLOOKUP(Settings!$B$12,Managers!$B$4:$B$15,Managers!$H$4:$H$15),$AH6))))} -> 48 | AJ6: =IF($A6="","",IF($AA6="Sold","Sold",IF($I6="Yes","Budget Drainer",IF($G6>=8,"Target",IF($Z6>$Y6*1.15,"Budget Drainer",IF($Y6>$Z6*1.15,"Value Target","Recommended")))))) -> Recommended | AK6: =IF($A6="","",IF($AA6="Sold",0,ROUND($Y6+$G6*5+IF($AJ6="Budget Drainer",MAX(0,$Z6-$Y6),0),0))) -> 71 | AL6: =IF($A6="","",IF($I6="Yes","Avoid unless cheap",IF($J6<>"Low","Check transfer risk","")))
A7: *06mn0* | B7: Igor Thiago | C7: BRF | D7: FWD | E7: FWD | F7: Tier 1 | G7: 6 | H7: 7 | I7: No | J7: Low | L7: 452 | M7: 11.89 | P7: =IF($A7="","",IFERROR((IF($O7="",0,$O7)*Settings!$J$4+IF($L7="",0,$L7)*Settings!$J$5+IF($N7="",0,$N7)*Settings!$J$6)/(IF($O7="",0,Settings!$J$4)+IF($L7="",0,Settings!$J$5)+IF($N7="",0,Settings!$J$6)),0)) -> 452 | Q7: {=IF($A7="","",XLOOKUP($E7,Settings!$A$19:$A$22,Settings!$G$19:$G$22,0))} -> 203 | R7: =IF($A7="","",MAX(0,$P7-$Q7)) -> 249 | S7: =IF($A7="","",IF($R7<=0,1,1+$R7/SUMIF($R$4:$R$923,">0",$R$4:$R$923)*(Settings!$B$5*(Settings!$B$6-Settings!$B$7)))) -> 31.74416 | T7: {=IF($A7="","",XLOOKUP($F7,Settings!$I$15:$I$20,Settings!$J$15:$J$20,1))} -> 1.15 | U7: =IF($A7="","",1+(($G7-5)/5)*Settings!$J$8) -> 1.03 | V7: =IF($A7="","",1+(($H7-5)/5)*Settings!$J$9) -> 1.06 | W7: {=IF($A7="","",XLOOKUP($J7,Lists!$C$3:$C$7,Lists!$D$3:$D$7,1))} -> 1 | X7: =IF($A7="","",IF($I7="Yes",Settings!$J$10,1)) -> 1 | Y7: =IF($A7="","",MAX(1,ROUND($S7*$T7*$U7*$V7*$W7*$X7,0))) -> 40 | Z7: =IF($A7="","",IFERROR(ROUND(AVERAGEIFS('Historical Drafts'!$G$4:$G$300,'Historical Drafts'!$D$4:$D$300,$E7,'Historical Drafts'!$J$4:$J$300,">="&$L7*0.85,'Historical Drafts'!$J$4:$J$300,"<="&$L7*1.15),0),$Y7)) -> 40 | AA7: =IF($A7="","",IF(COUNTIF('Auction Log'!$B$3:$B$300,$A7)>0,"Sold","Available")) -> Available | AB7: {=IF($A7="","",IFERROR(XLOOKUP($A7,'Auction Log'!$B$3:$B$300,'Auction Log'!$G$3:$G$300,""),""))} | AC7: {=IF($A7="","",IFERROR(XLOOKUP($A7,'Auction Log'!$B$3:$B$300,'Auction Log'!$F$3:$F$300,""),""))} | AD7: {=IF($A7="","",ROUND($Y7*XLOOKUP($F7,Settings!$I$15:$I$20,Settings!$K$15:$K$20,0.4),0))} -> 18 | AE7: {=IF($A7="","",ROUND($Y7*XLOOKUP($F7,Settings!$I$15:$I$20,Settings!$L$15:$L$20,0.8),0))} -> 32 | AF7: {=IF($A7="","",ROUND($Y7*XLOOKUP($F7,Settings!$I$15:$I$20,Settings!$M$15:$M$20,1),0))} -> 40 | AG7: {=IF($A7="","",ROUND($Y7*XLOOKUP($F7,Settings!$I$15:$I$20,Settings!$N$15:$N$20,1.1),0))} -> 44 | AH7: {=IF($A7="","",ROUND($Y7*XLOOKUP($F7,Settings!$I$15:$I$20,Settings!$O$15:$O$20,1.1)*Settings!$J$7,0))} -> 47 | AI7: {=IF($A7="","",IF($AA7="Sold","",MIN($AH7,IFERROR(XLOOKUP(Settings!$B$12,Managers!$B$4:$B$15,Managers!$H$4:$H$15),$AH7))))} -> 47 | AJ7: =IF($A7="","",IF($AA7="Sold","Sold",IF($I7="Yes","Budget Drainer",IF($G7>=8,"Target",IF($Z7>$Y7*1.15,"Budget Drainer",IF($Y7>$Z7*1.15,"Value Target","Recommended")))))) -> Recommended | AK7: =IF($A7="","",IF($AA7="Sold",0,ROUND($Y7+$G7*5+IF($AJ7="Budget Drainer",MAX(0,$Z7-$Y7),0),0))) -> 70 | AL7: =IF($A7="","",IF($I7="Yes","Avoid unless cheap",IF($J7<>"Low","Check transfer risk","")))
A8: *04y92* | B8: Bukayo Saka | C8: ARS | D8: MID | E8: MID | F8: Tier 1 | G8: 6 | H8: 7 | I8: No | J8: Low | L8: 437.5 | M8: 14.11 | P8: =IF($A8="","",IFERROR((IF($O8="",0,$O8)*Settings!$J$4+IF($L8="",0,$L8)*Settings!$J$5+IF($N8="",0,$N8)*Settings!$J$6)/(IF($O8="",0,Settings!$J$4)+IF($L8="",0,Settings!$J$5)+IF($N8="",0,Settings!$J$6)),0)) -> 437.5 | Q8: {=IF($A8="","",XLOOKUP($E8,Settings!$A$19:$A$22,Settings!$G$19:$G$22,0))} -> 206 | R8: =IF($A8="","",MAX(0,$P8-$Q8)) -> 231.5 | S8: =IF($A8="","",IF($R8<=0,1,1+$R8/SUMIF($R$4:$R$923,">0",$R$4:$R$923)*(Settings!$B$5*(Settings!$B$6-Settings!$B$7)))) -> 29.583426 | T8: {=IF($A8="","",XLOOKUP($F8,Settings!$I$15:$I$20,Settings!$J$15:$J$20,1))} -> 1.15 | U8: =IF($A8="","",1+(($G8-5)/5)*Settings!$J$8) -> 1.03 | V8: =IF($A8="","",1+(($H8-5)/5)*Settings!$J$9) -> 1.06 | W8: {=IF($A8="","",XLOOKUP($J8,Lists!$C$3:$C$7,Lists!$D$3:$D$7,1))} -> 1 | X8: =IF($A8="","",IF($I8="Yes",Settings!$J$10,1)) -> 1 | Y8: =IF($A8="","",MAX(1,ROUND($S8*$T8*$U8*$V8*$W8*$X8,0))) -> 37 | Z8: =IF($A8="","",IFERROR(ROUND(AVERAGEIFS('Historical Drafts'!$G$4:$G$300,'Historical Drafts'!$D$4:$D$300,$E8,'Historical Drafts'!$J$4:$J$300,">="&$L8*0.85,'Historical Drafts'!$J$4:$J$300,"<="&$L8*1.15),0),$Y8)) -> 26 | AA8: =IF($A8="","",IF(COUNTIF('Auction Log'!$B$3:$B$300,$A8)>0,"Sold","Available")) -> Available | AB8: {=IF($A8="","",IFERROR(XLOOKUP($A8,'Auction Log'!$B$3:$B$300,'Auction Log'!$G$3:$G$300,""),""))} | AC8: {=IF($A8="","",IFERROR(XLOOKUP($A8,'Auction Log'!$B$3:$B$300,'Auction Log'!$F$3:$F$300,""),""))} | AD8: {=IF($A8="","",ROUND($Y8*XLOOKUP($F8,Settings!$I$15:$I$20,Settings!$K$15:$K$20,0.4),0))} -> 17 | AE8: {=IF($A8="","",ROUND($Y8*XLOOKUP($F8,Settings!$I$15:$I$20,Settings!$L$15:$L$20,0.8),0))} -> 30 | AF8: {=IF($A8="","",ROUND($Y8*XLOOKUP($F8,Settings!$I$15:$I$20,Settings!$M$15:$M$20,1),0))} -> 37 | AG8: {=IF($A8="","",ROUND($Y8*XLOOKUP($F8,Settings!$I$15:$I$20,Settings!$N$15:$N$20,1.1),0))} -> 41 | AH8: {=IF($A8="","",ROUND($Y8*XLOOKUP($F8,Settings!$I$15:$I$20,Settings!$O$15:$O$20,1.1)*Settings!$J$7,0))} -> 44 | AI8: {=IF($A8="","",IF($AA8="Sold","",MIN($AH8,IFERROR(XLOOKUP(Settings!$B$12,Managers!$B$4:$B$15,Managers!$H$4:$H$15),$AH8))))} -> 44 | AJ8: =IF($A8="","",IF($AA8="Sold","Sold",IF($I8="Yes","Budget Drainer",IF($G8>=8,"Target",IF($Z8>$Y8*1.15,"Budget Drainer",IF($Y8>$Z8*1.15,"Value Target","Recommended")))))) -> Value Target | AK8: =IF($A8="","",IF($AA8="Sold",0,ROUND($Y8+$G8*5+IF($AJ8="Budget Drainer",MAX(0,$Z8-$Y8),0),0))) -> 67 | AL8: =IF($A8="","",IF($I8="Yes","Avoid unless cheap",IF($J8<>"Low","Check transfer risk","")))
A9: *04qr9* | B9: Morgan Gibbs-White | C9: NOT | D9: MID | E9: MID | F9: Tier 1 | G9: 6 | H9: 7 | I9: No | J9: Low | L9: 435.5 | M9: 11.77 | P9: =IF($A9="","",IFERROR((IF($O9="",0,$O9)*Settings!$J$4+IF($L9="",0,$L9)*Settings!$J$5+IF($N9="",0,$N9)*Settings!$J$6)/(IF($O9="",0,Settings!$J$4)+IF($L9="",0,Settings!$J$5)+IF($N9="",0,Settings!$J$6)),0)) -> 435.5 | Q9: {=IF($A9="","",XLOOKUP($E9,Settings!$A$19:$A$22,Settings!$G$19:$G$22,0))} -> 206 | R9: =IF($A9="","",MAX(0,$P9-$Q9)) -> 229.5 | S9: =IF($A9="","",IF($R9<=0,1,1+$R9/SUMIF($R$4:$R$923,">0",$R$4:$R$923)*(Settings!$B$5*(Settings!$B$6-Settings!$B$7)))) -> 29.336485 | T9: {=IF($A9="","",XLOOKUP($F9,Settings!$I$15:$I$20,Settings!$J$15:$J$20,1))} -> 1.15 | U9: =IF($A9="","",1+(($G9-5)/5)*Settings!$J$8) -> 1.03 | V9: =IF($A9="","",1+(($H9-5)/5)*Settings!$J$9) -> 1.06 | W9: {=IF($A9="","",XLOOKUP($J9,Lists!$C$3:$C$7,Lists!$D$3:$D$7,1))} -> 1 | X9: =IF($A9="","",IF($I9="Yes",Settings!$J$10,1)) -> 1 | Y9: =IF($A9="","",MAX(1,ROUND($S9*$T9*$U9*$V9*$W9*$X9,0))) -> 37 | Z9: =IF($A9="","",IFERROR(ROUND(AVERAGEIFS('Historical Drafts'!$G$4:$G$300,'Historical Drafts'!$D$4:$D$300,$E9,'Historical Drafts'!$J$4:$J$300,">="&$L9*0.85,'Historical Drafts'!$J$4:$J$300,"<="&$L9*1.15),0),$Y9)) -> 26 | AA9: =IF($A9="","",IF(COUNTIF('Auction Log'!$B$3:$B$300,$A9)>0,"Sold","Available")) -> Available | AB9: {=IF($A9="","",IFERROR(XLOOKUP($A9,'Auction Log'!$B$3:$B$300,'Auction Log'!$G$3:$G$300,""),""))} | AC9: {=IF($A9="","",IFERROR(XLOOKUP($A9,'Auction Log'!$B$3:$B$300,'Auction Log'!$F$3:$F$300,""),""))} | AD9: {=IF($A9="","",ROUND($Y9*XLOOKUP($F9,Settings!$I$15:$I$20,Settings!$K$15:$K$20,0.4),0))} -> 17 | AE9: {=IF($A9="","",ROUND($Y9*XLOOKUP($F9,Settings!$I$15:$I$20,Settings!$L$15:$L$20,0.8),0))} -> 30 | AF9: {=IF($A9="","",ROUND($Y9*XLOOKUP($F9,Settings!$I$15:$I$20,Settings!$M$15:$M$20,1),0))} -> 37 | AG9: {=IF($A9="","",ROUND($Y9*XLOOKUP($F9,Settings!$I$15:$I$20,Settings!$N$15:$N$20,1.1),0))} -> 41 | AH9: {=IF($A9="","",ROUND($Y9*XLOOKUP($F9,Settings!$I$15:$I$20,Settings!$O$15:$O$20,1.1)*Settings!$J$7,0))} -> 44 | AI9: {=IF($A9="","",IF($AA9="Sold","",MIN($AH9,IFERROR(XLOOKUP(Settings!$B$12,Managers!$B$4:$B$15,Managers!$H$4:$H$15),$AH9))))} -> 44 | AJ9: =IF($A9="","",IF($AA9="Sold","Sold",IF($I9="Yes","Budget Drainer",IF($G9>=8,"Target",IF($Z9>$Y9*1.15,"Budget Drainer",IF($Y9>$Z9*1.15,"Value Target","Recommended")))))) -> Value Target | AK9: =IF($A9="","",IF($AA9="Sold",0,ROUND($Y9+$G9*5+IF($AJ9="Budget Drainer",MAX(0,$Z9-$Y9),0),0))) -> 67 | AL9: =IF($A9="","",IF($I9="Yes","Avoid unless cheap",IF($J9<>"Low","Check transfer risk","")))
A10: *046c5* | B10: Jarrod Bowen | C10: WHU | D10: FWD | E10: FWD | F10: Tier 1 | G10: 5 | H10: 7 | I10: No | J10: Low | L10: 431 | M10: 11.34 | P10: =IF($A10="","",IFERROR((IF($O10="",0,$O10)*Settings!$J$4+IF($L10="",0,$L10)*Settings!$J$5+IF($N10="",0,$N10)*Settings!$J$6)/(IF($O10="",0,Settings!$J$4)+IF($L10="",0,Settings!$J$5)+IF($N10="",0,Settings!$J$6)),0)) -> 431 | Q10: {=IF($A10="","",XLOOKUP($E10,Settings!$A$19:$A$22,Settings!$G$19:$G$22,0))} -> 203 | R10: =IF($A10="","",MAX(0,$P10-$Q10)) -> 228 | S10: =IF($A10="","",IF($R10<=0,1,1+$R10/SUMIF($R$4:$R$923,">0",$R$4:$R$923)*(Settings!$B$5*(Settings!$B$6-Settings!$B$7)))) -> 29.151279 | T10: {=IF($A10="","",XLOOKUP($F10,Settings!$I$15:$I$20,Settings!$J$15:$J$20,1))} -> 1.15 | U10: =IF($A10="","",1+(($G10-5)/5)*Settings!$J$8) -> 1 | V10: =IF($A10="","",1+(($H10-5)/5)*Settings!$J$9) -> 1.06 | W10: {=IF($A10="","",XLOOKUP($J10,Lists!$C$3:$C$7,Lists!$D$3:$D$7,1))} -> 1 | X10: =IF($A10="","",IF($I10="Yes",Settings!$J$10,1)) -> 1 | Y10: =IF($A10="","",MAX(1,ROUND($S10*$T10*$U10*$V10*$W10*$X10,0))) -> 36 | Z10: =IF($A10="","",IFERROR(ROUND(AVERAGEIFS('Historical Drafts'!$G$4:$G$300,'Historical Drafts'!$D$4:$D$300,$E10,'Historical Drafts'!$J$4:$J$300,">="&$L10*0.85,'Historical Drafts'!$J$4:$J$300,"<="&$L10*1.15),0),$Y10)) -> 40 | AA10: =IF($A10="","",IF(COUNTIF('Auction Log'!$B$3:$B$300,$A10)>0,"Sold","Available")) -> Available | AB10: {=IF($A10="","",IFERROR(XLOOKUP($A10,'Auction Log'!$B$3:$B$300,'Auction Log'!$G$3:$G$300,""),""))} | AC10: {=IF($A10="","",IFERROR(XLOOKUP($A10,'Auction Log'!$B$3:$B$300,'Auction Log'!$F$3:$F$300,""),""))} | AD10: {=IF($A10="","",ROUND($Y10*XLOOKUP($F10,Settings!$I$15:$I$20,Settings!$K$15:$K$20,0.4),0))} -> 16 | AE10: {=IF($A10="","",ROUND($Y10*XLOOKUP($F10,Settings!$I$15:$I$20,Settings!$L$15:$L$20,0.8),0))} -> 29 | AF10: {=IF($A10="","",ROUND($Y10*XLOOKUP($F10,Settings!$I$15:$I$20,Settings!$M$15:$M$20,1),0))} -> 36 | AG10: {=IF($A10="","",ROUND($Y10*XLOOKUP($F10,Settings!$I$15:$I$20,Settings!$N$15:$N$20,1.1),0))} -> 40 | AH10: {=IF($A10="","",ROUND($Y10*XLOOKUP($F10,Settings!$I$15:$I$20,Settings!$O$15:$O$20,1.1)*Settings!$J$7,0))} -> 42 | AI10: {=IF($A10="","",IF($AA10="Sold","",MIN($AH10,IFERROR(XLOOKUP(Settings!$B$12,Managers!$B$4:$B$15,Managers!$H$4:$H$15),$AH10))))} -> 42 | AJ10: =IF($A10="","",IF($AA10="Sold","Sold",IF($I10="Yes","Budget Drainer",IF($G10>=8,"Target",IF($Z10>$Y10*1.15,"Budget Drainer",IF($Y10>$Z10*1.15,"Value Target","Recommended")))))) -> Recommended | AK10: =IF($A10="","",IF($AA10="Sold",0,ROUND($Y10+$G10*5+IF($AJ10="Budget Drainer",MAX(0,$Z10-$Y10),0),0))) -> 61 | AL10: =IF($A10="","",IF($I10="Yes","Avoid unless cheap",IF($J10<>"Low","Check transfer risk","")))
A11: *04agz* | B11: Declan Rice | C11: ARS | D11: MID | E11: MID | F11: Tier 1 | G11: 5 | H11: 7 | I11: No | J11: Low | L11: 420 | M11: 11.67 | P11: =IF($A11="","",IFERROR((IF($O11="",0,$O11)*Settings!$J$4+IF($L11="",0,$L11)*Settings!$J$5+IF($N11="",0,$N11)*Settings!$J$6)/(IF($O11="",0,Settings!$J$4)+IF($L11="",0,Settings!$J$5)+IF($N11="",0,Settings!$J$6)),0)) -> 420 | Q11: {=IF($A11="","",XLOOKUP($E11,Settings!$A$19:$A$22,Settings!$G$19:$G$22,0))} -> 206 | R11: =IF($A11="","",MAX(0,$P11-$Q11)) -> 214 | S11: =IF($A11="","",IF($R11<=0,1,1+$R11/SUMIF($R$4:$R$923,">0",$R$4:$R$923)*(Settings!$B$5*(Settings!$B$6-Settings!$B$7)))) -> 27.422692 | T11: {=IF($A11="","",XLOOKUP($F11,Settings!$I$15:$I$20,Settings!$J$15:$J$20,1))} -> 1.15 | U11: =IF($A11="","",1+(($G11-5)/5)*Settings!$J$8) -> 1 | V11: =IF($A11="","",1+(($H11-5)/5)*Settings!$J$9) -> 1.06 | W11: {=IF($A11="","",XLOOKUP($J11,Lists!$C$3:$C$7,Lists!$D$3:$D$7,1))} -> 1 | X11: =IF($A11="","",IF($I11="Yes",Settings!$J$10,1)) -> 1 | Y11: =IF($A11="","",MAX(1,ROUND($S11*$T11*$U11*$V11*$W11*$X11,0))) -> 33 | Z11: =IF($A11="","",IFERROR(ROUND(AVERAGEIFS('Historical Drafts'!$G$4:$G$300,'Historical Drafts'!$D$4:$D$300,$E11,'Historical Drafts'!$J$4:$J$300,">="&$L11*0.85,'Historical Drafts'!$J$4:$J$300,"<="&$L11*1.15),0),$Y11)) -> 23 | AA11: =IF($A11="","",IF(COUNTIF('Auction Log'!$B$3:$B$300,$A11)>0,"Sold","Available")) -> Available | AB11: {=IF($A11="","",IFERROR(XLOOKUP($A11,'Auction Log'!$B$3:$B$300,'Auction Log'!$G$3:$G$300,""),""))} | AC11: {=IF($A11="","",IFERROR(XLOOKUP($A11,'Auction Log'!$B$3:$B$300,'Auction Log'!$F$3:$F$300,""),""))} | AD11: {=IF($A11="","",ROUND($Y11*XLOOKUP($F11,Settings!$I$15:$I$20,Settings!$K$15:$K$20,0.4),0))} -> 15 | AE11: {=IF($A11="","",ROUND($Y11*XLOOKUP($F11,Settings!$I$15:$I$20,Settings!$L$15:$L$20,0.8),0))} -> 26 | AF11: {=IF($A11="","",ROUND($Y11*XLOOKUP($F11,Settings!$I$15:$I$20,Settings!$M$15:$M$20,1),0))} -> 33 | AG11: {=IF($A11="","",ROUND($Y11*XLOOKUP($F11,Settings!$I$15:$I$20,Settings!$N$15:$N$20,1.1),0))} -> 36 | AH11: {=IF($A11="","",ROUND($Y11*XLOOKUP($F11,Settings!$I$15:$I$20,Settings!$O$15:$O$20,1.1)*Settings!$J$7,0))} -> 39 | AI11: {=IF($A11="","",IF($AA11="Sold","",MIN($AH11,IFERROR(XLOOKUP(Settings!$B$12,Managers!$B$4:$B$15,Managers!$H$4:$H$15),$AH11))))} -> 39 | AJ11: =IF($A11="","",IF($AA11="Sold","Sold",IF($I11="Yes","Budget Drainer",IF($G11>=8,"Target",IF($Z11>$Y11*1.15,"Budget Drainer",IF($Y11>$Z11*1.15,"Value Target","Recommended")))))) -> Value Target | AK11: =IF($A11="","",IF($AA11="Sold",0,ROUND($Y11+$G11*5+IF($AJ11="Budget Drainer",MAX(0,$Z11-$Y11),0),0))) -> 58 | AL11: =IF($A11="","",IF($I11="Yes","Avoid unless cheap",IF($J11<>"Low","Check transfer risk","")))
A12: *06cmm* | B12: Dominik Szoboszlai | C12: LIV | D12: MID | E12: MID | F12: Tier 1 | G12: 5 | H12: 7 | I12: No | J12: Low | L12: 415.5 | M12: 11.54 | P12: =IF($A12="","",IFERROR((IF($O12="",0,$O12)*Settings!$J$4+IF($L12="",0,$L12)*Settings!$J$5+IF($N12="",0,$N12)*Settings!$J$6)/(IF($O12="",0,Settings!$J$4)+IF($L12="",0,Settings!$J$5)+IF($N12="",0,Settings!$J$6)),0)) -> 415.5 | Q12: {=IF($A12="","",XLOOKUP($E12,Settings!$A$19:$A$22,Settings!$G$19:$G$22,0))} -> 206 | R12: =IF($A12="","",MAX(0,$P12-$Q12)) -> 209.5 | S12: =IF($A12="","",IF($R12<=0,1,1+$R12/SUMIF($R$4:$R$923,">0",$R$4:$R$923)*(Settings!$B$5*(Settings!$B$6-Settings!$B$7)))) -> 26.867075 | T12: {=IF($A12="","",XLOOKUP($F12,Settings!$I$15:$I$20,Settings!$J$15:$J$20,1))} -> 1.15 | U12: =IF($A12="","",1+(($G12-5)/5)*Settings!$J$8) -> 1 | V12: =IF($A12="","",1+(($H12-5)/5)*Settings!$J$9) -> 1.06 | W12: {=IF($A12="","",XLOOKUP($J12,Lists!$C$3:$C$7,Lists!$D$3:$D$7,1))} -> 1 | X12: =IF($A12="","",IF($I12="Yes",Settings!$J$10,1)) -> 1 | Y12: =IF($A12="","",MAX(1,ROUND($S12*$T12*$U12*$V12*$W12*$X12,0))) -> 33 | Z12: =IF($A12="","",IFERROR(ROUND(AVERAGEIFS('Historical Drafts'!$G$4:$G$300,'Historical Drafts'!$D$4:$D$300,$E12,'Historical Drafts'!$J$4:$J$300,">="&$L12*0.85,'Historical Drafts'!$J$4:$J$300,"<="&$L12*1.15),0),$Y12)) -> 21 | AA12: =IF($A12="","",IF(COUNTIF('Auction Log'!$B$3:$B$300,$A12)>0,"Sold","Available")) -> Available | AB12: {=IF($A12="","",IFERROR(XLOOKUP($A12,'Auction Log'!$B$3:$B$300,'Auction Log'!$G$3:$G$300,""),""))} | AC12: {=IF($A12="","",IFERROR(XLOOKUP($A12,'Auction Log'!$B$3:$B$300,'Auction Log'!$F$3:$F$300,""),""))} | AD12: {=IF($A12="","",ROUND($Y12*XLOOKUP($F12,Settings!$I$15:$I$20,Settings!$K$15:$K$20,0.4),0))} -> 15 | AE12: {=IF($A12="","",ROUND($Y12*XLOOKUP($F12,Settings!$I$15:$I$20,Settings!$L$15:$L$20,0.8),0))} -> 26 | AF12: {=IF($A12="","",ROUND($Y12*XLOOKUP($F12,Settings!$I$15:$I$20,Settings!$M$15:$M$20,1),0))} -> 33 | AG12: {=IF($A12="","",ROUND($Y12*XLOOKUP($F12,Settings!$I$15:$I$20,Settings!$N$15:$N$20,1.1),0))} -> 36 | AH12: {=IF($A12="","",ROUND($Y12*XLOOKUP($F12,Settings!$I$15:$I$20,Settings!$O$15:$O$20,1.1)*Settings!$J$7,0))} -> 39 | AI12: {=IF($A12="","",IF($AA12="Sold","",MIN($AH12,IFERROR(XLOOKUP(Settings!$B$12,Managers!$B$4:$B$15,Managers!$H$4:$H$15),$AH12))))} -> 39 | AJ12: =IF($A12="","",IF($AA12="Sold","Sold",IF($I12="Yes","Budget Drainer",IF($G12>=8,"Target",IF($Z12>$Y12*1.15,"Budget Drainer",IF($Y12>$Z12*1.15,"Value Target","Recommended")))))) -> Value Target | AK12: =IF($A12="","",IF($AA12="Sold",0,ROUND($Y12+$G12*5+IF($AJ12="Budget Drainer",MAX(0,$Z12-$Y12),0),0))) -> 58 | AL12: =IF($A12="","",IF($I12="Yes","Avoid unless cheap",IF($J12<>"Low","Check transfer risk","")))
A13: *05opj* | B13: Elliot Anderson | C13: NOT | D13: MID | E13: MID | F13: Tier 1 | G13: 5 | H13: 7 | I13: No | J13: Low | L13: 405 | M13: 10.66 | P13: =IF($A13="","",IFERROR((IF($O13="",0,$O13)*Settings!$J$4+IF($L13="",0,$L13)*Settings!$J$5+IF($N13="",0,$N13)*Settings!$J$6)/(IF($O13="",0,Settings!$J$4)+IF($L13="",0,Settings!$J$5)+IF($N13="",0,Settings!$J$6)),0)) -> 405 | Q13: {=IF($A13="","",XLOOKUP($E13,Settings!$A$19:$A$22,Settings!$G$19:$G$22,0))} -> 206 | R13: =IF($A13="","",MAX(0,$P13-$Q13)) -> 199 | S13: =IF($A13="","",IF($R13<=0,1,1+$R13/SUMIF($R$4:$R$923,">0",$R$4:$R$923)*(Settings!$B$5*(Settings!$B$6-Settings!$B$7)))) -> 25.570634 | T13: {=IF($A13="","",XLOOKUP($F13,Settings!$I$15:$I$20,Settings!$J$15:$J$20,1))} -> 1.15 | U13: =IF($A13="","",1+(($G13-5)/5)*Settings!$J$8) -> 1 | V13: =IF($A13="","",1+(($H13-5)/5)*Settings!$J$9) -> 1.06 | W13: {=IF($A13="","",XLOOKUP($J13,Lists!$C$3:$C$7,Lists!$D$3:$D$7,1))} -> 1 | X13: =IF($A13="","",IF($I13="Yes",Settings!$J$10,1)) -> 1 | Y13: =IF($A13="","",MAX(1,ROUND($S13*$T13*$U13*$V13*$W13*$X13,0))) -> 31 | Z13: =IF($A13="","",IFERROR(ROUND(AVERAGEIFS('Historical Drafts'!$G$4:$G$300,'Historical Drafts'!$D$4:$D$300,$E13,'Historical Drafts'!$J$4:$J$300,">="&$L13*0.85,'Historical Drafts'!$J$4:$J$300,"<="&$L13*1.15),0),$Y13)) -> 20 | AA13: =IF($A13="","",IF(COUNTIF('Auction Log'!$B$3:$B$300,$A13)>0,"Sold","Available")) -> Available | AB13: {=IF($A13="","",IFERROR(XLOOKUP($A13,'Auction Log'!$B$3:$B$300,'Auction Log'!$G$3:$G$300,""),""))} | AC13: {=IF($A13="","",IFERROR(XLOOKUP($A13,'Auction Log'!$B$3:$B$300,'Auction Log'!$F$3:$F$300,""),""))} | AD13: {=IF($A13="","",ROUND($Y13*XLOOKUP($F13,Settings!$I$15:$I$20,Settings!$K$15:$K$20,0.4),0))} -> 14 | AE13: {=IF($A13="","",ROUND($Y13*XLOOKUP($F13,Settings!$I$15:$I$20,Settings!$L$15:$L$20,0.8),0))} -> 25 | AF13: {=IF($A13="","",ROUND($Y13*XLOOKUP($F13,Settings!$I$15:$I$20,Settings!$M$15:$M$20,1),0))} -> 31 | AG13: {=IF($A13="","",ROUND($Y13*XLOOKUP($F13,Settings!$I$15:$I$20,Settings!$N$15:$N$20,1.1),0))} -> 34 | AH13: {=IF($A13="","",ROUND($Y13*XLOOKUP($F13,Settings!$I$15:$I$20,Settings!$O$15:$O$20,1.1)*Settings!$J$7,0))} -> 37 | AI13: {=IF($A13="","",IF($AA13="Sold","",MIN($AH13,IFERROR(XLOOKUP(Settings!$B$12,Managers!$B$4:$B$15,Managers!$H$4:$H$15),$AH13))))} -> 37 | AJ13: =IF($A13="","",IF($AA13="Sold","Sold",IF($I13="Yes","Budget Drainer",IF($G13>=8,"Target",IF($Z13>$Y13*1.15,"Budget Drainer",IF($Y13>$Z13*1.15,"Value Target","Recommended")))))) -> Value Target | AK13: =IF($A13="","",IF($AA13="Sold",0,ROUND($Y13+$G13*5+IF($AJ13="Budget Drainer",MAX(0,$Z13-$Y13),0),0))) -> 56 | AL13: =IF($A13="","",IF($I13="Yes","Avoid unless cheap",IF($J13<>"Low","Check transfer risk","")))
A14: *05g2o* | B14: Joao Pedro | C14: CHE | D14: FWD | E14: FWD | F14: Tier 1 | G14: 5 | H14: 7 | I14: No | J14: Low | L14: 393 | M14: 11.23 | P14: =IF($A14="","",IFERROR((IF($O14="",0,$O14)*Settings!$J$4+IF($L14="",0,$L14)*Settings!$J$5+IF($N14="",0,$N14)*Settings!$J$6)/(IF($O14="",0,Settings!$J$4)+IF($L14="",0,Settings!$J$5)+IF($N14="",0,Settings!$J$6)),0)) -> 393 | Q14: {=IF($A14="","",XLOOKUP($E14,Settings!$A$19:$A$22,Settings!$G$19:$G$22,0))} -> 203 | R14: =IF($A14="","",MAX(0,$P14-$Q14)) -> 190 | S14: =IF($A14="","",IF($R14<=0,1,1+$R14/SUMIF($R$4:$R$923,">0",$R$4:$R$923)*(Settings!$B$5*(Settings!$B$6-Settings!$B$7)))) -> 24.459399 | T14: {=IF($A14="","",XLOOKUP($F14,Settings!$I$15:$I$20,Settings!$J$15:$J$20,1))} -> 1.15 | U14: =IF($A14="","",1+(($G14-5)/5)*Settings!$J$8) -> 1 | V14: =IF($A14="","",1+(($H14-5)/5)*Settings!$J$9) -> 1.06 | W14: {=IF($A14="","",XLOOKUP($J14,Lists!$C$3:$C$7,Lists!$D$3:$D$7,1))} -> 1 | X14: =IF($A14="","",IF($I14="Yes",Settings!$J$10,1)) -> 1 | Y14: =IF($A14="","",MAX(1,ROUND($S14*$T14*$U14*$V14*$W14*$X14,0))) -> 30 | Z14: =IF($A14="","",IFERROR(ROUND(AVERAGEIFS('Historical Drafts'!$G$4:$G$300,'Historical Drafts'!$D$4:$D$300,$E14,'Historical Drafts'!$J$4:$J$300,">="&$L14*0.85,'Historical Drafts'!$J$4:$J$300,"<="&$L14*1.15),0),$Y14)) -> 41 | AA14: =IF($A14="","",IF(COUNTIF('Auction Log'!$B$3:$B$300,$A14)>0,"Sold","Available")) -> Available | AB14: {=IF($A14="","",IFERROR(XLOOKUP($A14,'Auction Log'!$B$3:$B$300,'Auction Log'!$G$3:$G$300,""),""))} | AC14: {=IF($A14="","",IFERROR(XLOOKUP($A14,'Auction Log'!$B$3:$B$300,'Auction Log'!$F$3:$F$300,""),""))} | AD14: {=IF($A14="","",ROUND($Y14*XLOOKUP($F14,Settings!$I$15:$I$20,Settings!$K$15:$K$20,0.4),0))} -> 14 | AE14: {=IF($A14="","",ROUND($Y14*XLOOKUP($F14,Settings!$I$15:$I$20,Settings!$L$15:$L$20,0.8),0))} -> 24 | AF14: {=IF($A14="","",ROUND($Y14*XLOOKUP($F14,Settings!$I$15:$I$20,Settings!$M$15:$M$20,1),0))} -> 30 | AG14: {=IF($A14="","",ROUND($Y14*XLOOKUP($F14,Settings!$I$15:$I$20,Settings!$N$15:$N$20,1.1),0))} -> 33 | AH14: {=IF($A14="","",ROUND($Y14*XLOOKUP($F14,Settings!$I$15:$I$20,Settings!$O$15:$O$20,1.1)*Settings!$J$7,0))} -> 35 | AI14: {=IF($A14="","",IF($AA14="Sold","",MIN($AH14,IFERROR(XLOOKUP(Settings!$B$12,Managers!$B$4:$B$15,Managers!$H$4:$H$15),$AH14))))} -> 35 | AJ14: =IF($A14="","",IF($AA14="Sold","Sold",IF($I14="Yes","Budget Drainer",IF($G14>=8,"Target",IF($Z14>$Y14*1.15,"Budget Drainer",IF($Y14>$Z14*1.15,"Value Target","Recommended")))))) -> Budget Drainer | AK14: =IF($A14="","",IF($AA14="Sold",0,ROUND($Y14+$G14*5+IF($AJ14="Budget Drainer",MAX(0,$Z14-$Y14),0),0))) -> 66 | AL14: =IF($A14="","",IF($I14="Yes","Avoid unless cheap",IF($J14<>"Low","Check transfer risk","")))
A15: *04spw* | B15: James Garner | C15: EVE | D15: MID | E15: MID | F15: Tier 1 | G15: 5 | H15: 7 | I15: No | J15: Low | L15: 392.5 | M15: 10.33 | P15: =IF($A15="","",IFERROR((IF($O15="",0,$O15)*Settings!$J$4+IF($L15="",0,$L15)*Settings!$J$5+IF($N15="",0,$N15)*Settings!$J$6)/(IF($O15="",0,Settings!$J$4)+IF($L15="",0,Settings!$J$5)+IF($N15="",0,Settings!$J$6)),0)) -> 392.5 | Q15: {=IF($A15="","",XLOOKUP($E15,Settings!$A$19:$A$22,Settings!$G$19:$G$22,0))} -> 206 | R15: =IF($A15="","",MAX(0,$P15-$Q15)) -> 186.5 | S15: =IF($A15="","",IF($R15<=0,1,1+$R15/SUMIF($R$4:$R$923,">0",$R$4:$R$923)*(Settings!$B$5*(Settings!$B$6-Settings!$B$7)))) -> 24.027252 | T15: {=IF($A15="","",XLOOKUP($F15,Settings!$I$15:$I$20,Settings!$J$15:$J$20,1))} -> 1.15 | U15: =IF($A15="","",1+(($G15-5)/5)*Settings!$J$8) -> 1 | V15: =IF($A15="","",1+(($H15-5)/5)*Settings!$J$9) -> 1.06 | W15: {=IF($A15="","",XLOOKUP($J15,Lists!$C$3:$C$7,Lists!$D$3:$D$7,1))} -> 1 | X15: =IF($A15="","",IF($I15="Yes",Settings!$J$10,1)) -> 1 | Y15: =IF($A15="","",MAX(1,ROUND($S15*$T15*$U15*$V15*$W15*$X15,0))) -> 29 | Z15: =IF($A15="","",IFERROR(ROUND(AVERAGEIFS('Historical Drafts'!$G$4:$G$300,'Historical Drafts'!$D$4:$D$300,$E15,'Historical Drafts'!$J$4:$J$300,">="&$L15*0.85,'Historical Drafts'!$J$4:$J$300,"<="&$L15*1.15),0),$Y15)) -> 17 | AA15: =IF($A15="","",IF(COUNTIF('Auction Log'!$B$3:$B$300,$A15)>0,"Sold","Available")) -> Available | AB15: {=IF($A15="","",IFERROR(XLOOKUP($A15,'Auction Log'!$B$3:$B$300,'Auction Log'!$G$3:$G$300,""),""))} | AC15: {=IF($A15="","",IFERROR(XLOOKUP($A15,'Auction Log'!$B$3:$B$300,'Auction Log'!$F$3:$F$300,""),""))} | AD15: {=IF($A15="","",ROUND($Y15*XLOOKUP($F15,Settings!$I$15:$I$20,Settings!$K$15:$K$20,0.4),0))} -> 13 | AE15: {=IF($A15="","",ROUND($Y15*XLOOKUP($F15,Settings!$I$15:$I$20,Settings!$L$15:$L$20,0.8),0))} -> 23 | AF15: {=IF($A15="","",ROUND($Y15*XLOOKUP($F15,Settings!$I$15:$I$20,Settings!$M$15:$M$20,1),0))} -> 29 | AG15: {=IF($A15="","",ROUND($Y15*XLOOKUP($F15,Settings!$I$15:$I$20,Settings!$N$15:$N$20,1.1),0))} -> 32 | AH15: {=IF($A15="","",ROUND($Y15*XLOOKUP($F15,Settings!$I$15:$I$20,Settings!$O$15:$O$20,1.1)*Settings!$J$7,0))} -> 34 | AI15: {=IF($A15="","",IF($AA15="Sold","",MIN($AH15,IFERROR(XLOOKUP(Settings!$B$12,Managers!$B$4:$B$15,Managers!$H$4:$H$15),$AH15))))} -> 34 | AJ15: =IF($A15="","",IF($AA15="Sold","Sold",IF($I15="Yes","Budget Drainer",IF($G15>=8,"Target",IF($Z15>$Y15*1.15,"Budget Drainer",IF($Y15>$Z15*1.15,"Value Target","Recommended")))))) -> Value Target | AK15: =IF($A15="","",IF($AA15="Sold",0,ROUND($Y15+$G15*5+IF($AJ15="Budget Drainer",MAX(0,$Z15-$Y15),0),0))) -> 54 | AL15: =IF($A15="","",IF($I15="Yes","Avoid unless cheap",IF($J15<>"Low","Check transfer risk","")))
